2024-01-23T14:34:43|CRITICAL|root|Unhandled exception:Traceback (most recent call last):
  File "C:\Users\GiorgiaT\anaconda3\envs\scopefoundry1\lib\site-packages\ScopeFoundry\measurement.py", line 25, in run
    self.measurement._thread_run()
  File "C:\Users\GiorgiaT\anaconda3\envs\scopefoundry1\lib\site-packages\ScopeFoundry\measurement.py", line 230, in _thread_run
    self.run()
  File "C:\Users\GiorgiaT\OneDrive - Politecnico di Milano\Desktop\Python\ScopeFoundryProjects\Plant_Macroscope\plant_measure.py", line 157, in run
    self.measure()
  File "C:\Users\GiorgiaT\OneDrive - Politecnico di Milano\Desktop\Python\ScopeFoundryProjects\Plant_Macroscope\plant_measure.py", line 111, in measure
    self.dlp_hw.turn_on()
  File "C:\Users\GiorgiaT\OneDrive - Politecnico di Milano\Desktop\Python\ScopeFoundryProjects\DLP_IO_ScopeFoundry\io_hw.py", line 39, in turn_on
    self.dlp.write(self.ON1)
  File "C:\Users\GiorgiaT\anaconda3\envs\scopefoundry1\lib\site-packages\serial\serialwin32.py", line 317, in write
    raise SerialException("WriteFile failed ({!r})".format(ctypes.WinError()))
serial.serialutil.SerialException: WriteFile failed (PermissionError(13, 'Access is denied.', None, 5))

2024-01-23T14:34:46|ERROR|camera_app|tried to disconnect DLP_IO: WriteFile failed (PermissionError(13, 'Access is denied.', None, 5))
2024-01-23T14:51:14|ERROR|camera_app|tried to disconnect DLP_IO: WriteFile failed (PermissionError(13, 'Access is denied.', None, 5))
2024-01-23T14:54:25|ERROR|camera_app|tried to disconnect DLP_IO: WriteFile failed (PermissionError(13, 'Access is denied.', None, 5))
2024-01-23T15:23:10|ERROR|camera_app|tried to disconnect DLP_IO: WriteFile failed (PermissionError(13, 'Access is denied.', None, 5))
