2023-03-03T15:42:04|CRITICAL|root|Unhandled exception:TypeError: setValue(self, int): argument 1 has unexpected type 'float'

2023-03-03T15:42:07|CRITICAL|root|Unhandled exception:Traceback (most recent call last):
  File "C:\Users\GiorgiaT\anaconda3\envs\scopefoundry\lib\site-packages\ScopeFoundry\hardware.py", line 220, in enable_connection
    raise err
  File "C:\Users\GiorgiaT\anaconda3\envs\scopefoundry\lib\site-packages\ScopeFoundry\hardware.py", line 210, in enable_connection
    self.connect()
  File "C:\Users\GiorgiaT\OneDrive - Politecnico di Milano\Desktop\Python\ScopeFoundryProjects\DLP_IO_ScopeFoundry\io_hw.py", line 27, in connect
    self.dlp = Serial(port=self.port.val, baudrate=115200)
  File "C:\Users\GiorgiaT\anaconda3\envs\scopefoundry\lib\site-packages\serial\serialwin32.py", line 33, in __init__
    super(Serial, self).__init__(*args, **kwargs)
  File "C:\Users\GiorgiaT\anaconda3\envs\scopefoundry\lib\site-packages\serial\serialutil.py", line 244, in __init__
    self.open()
  File "C:\Users\GiorgiaT\anaconda3\envs\scopefoundry\lib\site-packages\serial\serialwin32.py", line 64, in open
    raise SerialException("could not open port {!r}: {!r}".format(self.portstr, ctypes.WinError()))
serial.serialutil.SerialException: could not open port 'COM8': FileNotFoundError(2, 'The system cannot find the file specified.', None, 2)

2023-03-03T15:42:10|CRITICAL|root|Unhandled exception:Traceback (most recent call last):
  File "C:\Users\GiorgiaT\anaconda3\envs\scopefoundry\lib\site-packages\ScopeFoundry\hardware.py", line 220, in enable_connection
    raise err
  File "C:\Users\GiorgiaT\anaconda3\envs\scopefoundry\lib\site-packages\ScopeFoundry\hardware.py", line 210, in enable_connection
    self.connect()
  File "C:\Users\GiorgiaT\OneDrive - Politecnico di Milano\Desktop\Python\ScopeFoundryProjects\DLP_IO_ScopeFoundry\io_hw.py", line 27, in connect
    self.dlp = Serial(port=self.port.val, baudrate=115200)
  File "C:\Users\GiorgiaT\anaconda3\envs\scopefoundry\lib\site-packages\serial\serialwin32.py", line 33, in __init__
    super(Serial, self).__init__(*args, **kwargs)
  File "C:\Users\GiorgiaT\anaconda3\envs\scopefoundry\lib\site-packages\serial\serialutil.py", line 244, in __init__
    self.open()
  File "C:\Users\GiorgiaT\anaconda3\envs\scopefoundry\lib\site-packages\serial\serialwin32.py", line 64, in open
    raise SerialException("could not open port {!r}: {!r}".format(self.portstr, ctypes.WinError()))
serial.serialutil.SerialException: could not open port 'COM8': FileNotFoundError(2, 'The system cannot find the file specified.', None, 2)

2023-03-03T15:42:49|CRITICAL|root|Unhandled exception:Traceback (most recent call last):
  File "C:\Users\GiorgiaT\anaconda3\envs\scopefoundry\lib\site-packages\ScopeFoundry\measurement.py", line 313, in start_stop
    self._start()
  File "C:\Users\GiorgiaT\anaconda3\envs\scopefoundry\lib\site-packages\ScopeFoundry\measurement.py", line 176, in _start
    self.display_update_timer.start(self.display_update_period*1000)
TypeError: arguments did not match any overloaded call:
  start(self, int): argument 1 has unexpected type 'float'
  start(self): too many arguments

2023-03-03T15:43:09|CRITICAL|root|Unhandled exception:Traceback (most recent call last):
  File "C:\Users\GiorgiaT\anaconda3\envs\scopefoundry\lib\site-packages\ScopeFoundry\measurement.py", line 25, in run
    self.measurement._thread_run()
  File "C:\Users\GiorgiaT\anaconda3\envs\scopefoundry\lib\site-packages\ScopeFoundry\measurement.py", line 230, in _thread_run
    self.run()
  File "C:\Users\GiorgiaT\OneDrive - Politecnico di Milano\Desktop\Python\ScopeFoundryProjects\Plant_Macroscope\plant_measure.py", line 150, in run
    self.img = self.image_gen.camera.get_nparray()
  File "C:\Users\GiorgiaT\OneDrive - Politecnico di Milano\Desktop\Python\ScopeFoundryProjects\Flir_ScopeFoundry\camera_device.py", line 68, in get_nparray
    return self.cam.get_array()
  File "C:\Users\GiorgiaT\anaconda3\envs\scopefoundry\lib\site-packages\simple_pyspin\__init__.py", line 221, in get_array
    img = self.cam.GetNextImage(PySpin.EVENT_TIMEOUT_INFINITE if wait else PySpin.EVENT_TIMEOUT_NONE)
  File "C:\Users\GiorgiaT\anaconda3\envs\scopefoundry\lib\site-packages\PySpin\PySpin.py", line 34318, in GetNextImage
    return _PySpin._SWIG_CamPtr_GetNextImage(self, *args)
_PySpin.SpinnakerException: Spinnaker: Stream is not started [-1010]

