2024-03-18T10:36:23|CRITICAL|root|Unhandled exception:Traceback (most recent call last):
  File "C:\Users\LAB\anaconda3\envs\scopefoundry\lib\site-packages\ScopeFoundry\hardware.py", line 220, in enable_connection
    raise err
  File "C:\Users\LAB\anaconda3\envs\scopefoundry\lib\site-packages\ScopeFoundry\hardware.py", line 210, in enable_connection
    self.connect()
  File "C:\Users\LAB\Scopefoundry_projects\DLP_IO_ScopeFoundry\io_hw.py", line 27, in connect
    self.dlp = Serial(port=self.port.val, baudrate=115200)
  File "C:\Users\LAB\anaconda3\envs\scopefoundry\lib\site-packages\serial\serialwin32.py", line 33, in __init__
    super(Serial, self).__init__(*args, **kwargs)
  File "C:\Users\LAB\anaconda3\envs\scopefoundry\lib\site-packages\serial\serialutil.py", line 244, in __init__
    self.open()
  File "C:\Users\LAB\anaconda3\envs\scopefoundry\lib\site-packages\serial\serialwin32.py", line 64, in open
    raise SerialException("could not open port {!r}: {!r}".format(self.portstr, ctypes.WinError()))
serial.serialutil.SerialException: could not open port 'COM3': FileNotFoundError(2, 'The system cannot find the file specified.', None, 2)

2024-03-18T17:17:53|CRITICAL|root|Unhandled exception:Traceback (most recent call last):
  File "C:\Users\LAB\anaconda3\envs\scopefoundry\lib\site-packages\ScopeFoundry\hardware.py", line 220, in enable_connection
    raise err
  File "C:\Users\LAB\anaconda3\envs\scopefoundry\lib\site-packages\ScopeFoundry\hardware.py", line 210, in enable_connection
    self.connect()
  File "C:\Users\LAB\Scopefoundry_projects\DLP_IO_ScopeFoundry\io_hw.py", line 27, in connect
    self.dlp = Serial(port=self.port.val, baudrate=115200)
  File "C:\Users\LAB\anaconda3\envs\scopefoundry\lib\site-packages\serial\serialwin32.py", line 33, in __init__
    super(Serial, self).__init__(*args, **kwargs)
  File "C:\Users\LAB\anaconda3\envs\scopefoundry\lib\site-packages\serial\serialutil.py", line 244, in __init__
    self.open()
  File "C:\Users\LAB\anaconda3\envs\scopefoundry\lib\site-packages\serial\serialwin32.py", line 64, in open
    raise SerialException("could not open port {!r}: {!r}".format(self.portstr, ctypes.WinError()))
serial.serialutil.SerialException: could not open port 'COM3': FileNotFoundError(2, 'The system cannot find the file specified.', None, 2)

