2023-04-03T09:52:31|CRITICAL|root|Unhandled exception:Traceback (most recent call last):
  File "C:\Users\GiorgiaT\anaconda3\envs\scopefoundry\lib\site-packages\ScopeFoundry\hardware.py", line 220, in enable_connection
    raise err
  File "C:\Users\GiorgiaT\anaconda3\envs\scopefoundry\lib\site-packages\ScopeFoundry\hardware.py", line 210, in enable_connection
    self.connect()
  File "C:\Users\GiorgiaT\OneDrive - Politecnico di Milano\Desktop\Python\ScopeFoundryProjects\DLP_IO_ScopeFoundry\io_hw.py", line 27, in connect
    self.dlp = Serial(port=self.port.val, baudrate=115200)
  File "C:\Users\GiorgiaT\anaconda3\envs\scopefoundry\lib\site-packages\serial\serialwin32.py", line 33, in __init__
    super(Serial, self).__init__(*args, **kwargs)
  File "C:\Users\GiorgiaT\anaconda3\envs\scopefoundry\lib\site-packages\serial\serialutil.py", line 244, in __init__
    self.open()
  File "C:\Users\GiorgiaT\anaconda3\envs\scopefoundry\lib\site-packages\serial\serialwin32.py", line 64, in open
    raise SerialException("could not open port {!r}: {!r}".format(self.portstr, ctypes.WinError()))
serial.serialutil.SerialException: could not open port 'COM3': FileNotFoundError(2, 'The system cannot find the file specified.', None, 2)

2023-04-03T09:52:32|CRITICAL|root|Unhandled exception:Traceback (most recent call last):
  File "C:\Users\GiorgiaT\anaconda3\envs\scopefoundry\lib\site-packages\ScopeFoundry\hardware.py", line 220, in enable_connection
    raise err
  File "C:\Users\GiorgiaT\anaconda3\envs\scopefoundry\lib\site-packages\ScopeFoundry\hardware.py", line 210, in enable_connection
    self.connect()
  File "C:\Users\GiorgiaT\OneDrive - Politecnico di Milano\Desktop\Python\ScopeFoundryProjects\DLP_IO_ScopeFoundry\io_hw.py", line 27, in connect
    self.dlp = Serial(port=self.port.val, baudrate=115200)
  File "C:\Users\GiorgiaT\anaconda3\envs\scopefoundry\lib\site-packages\serial\serialwin32.py", line 33, in __init__
    super(Serial, self).__init__(*args, **kwargs)
  File "C:\Users\GiorgiaT\anaconda3\envs\scopefoundry\lib\site-packages\serial\serialutil.py", line 244, in __init__
    self.open()
  File "C:\Users\GiorgiaT\anaconda3\envs\scopefoundry\lib\site-packages\serial\serialwin32.py", line 64, in open
    raise SerialException("could not open port {!r}: {!r}".format(self.portstr, ctypes.WinError()))
serial.serialutil.SerialException: could not open port 'COM3': FileNotFoundError(2, 'The system cannot find the file specified.', None, 2)

2023-04-03T09:55:06|CRITICAL|root|Unhandled exception:Traceback (most recent call last):
  File "C:\Users\GiorgiaT\anaconda3\envs\scopefoundry\lib\site-packages\ScopeFoundry\measurement.py", line 25, in run
    self.measurement._thread_run()
  File "C:\Users\GiorgiaT\anaconda3\envs\scopefoundry\lib\site-packages\ScopeFoundry\measurement.py", line 230, in _thread_run
    self.run()
  File "C:\Users\GiorgiaT\OneDrive - Politecnico di Milano\Desktop\Python\ScopeFoundryProjects\Plant_Macroscope\plant_measure.py", line 158, in run
    self.measure()
  File "C:\Users\GiorgiaT\OneDrive - Politecnico di Milano\Desktop\Python\ScopeFoundryProjects\Plant_Macroscope\plant_measure.py", line 111, in measure
    self.dlp_hw.turn_on()
  File "C:\Users\GiorgiaT\OneDrive - Politecnico di Milano\Desktop\Python\ScopeFoundryProjects\DLP_IO_ScopeFoundry\io_hw.py", line 39, in turn_on
    self.dlp.write(self.ON1)
AttributeError: 'IoHW' object has no attribute 'dlp'

2023-04-03T09:55:44|CRITICAL|root|Unhandled exception:Traceback (most recent call last):
  File "C:\Users\GiorgiaT\anaconda3\envs\scopefoundry\lib\site-packages\ScopeFoundry\measurement.py", line 25, in run
    self.measurement._thread_run()
  File "C:\Users\GiorgiaT\anaconda3\envs\scopefoundry\lib\site-packages\ScopeFoundry\measurement.py", line 230, in _thread_run
    self.run()
  File "C:\Users\GiorgiaT\OneDrive - Politecnico di Milano\Desktop\Python\ScopeFoundryProjects\Plant_Macroscope\plant_measure.py", line 158, in run
    self.measure()
  File "C:\Users\GiorgiaT\OneDrive - Politecnico di Milano\Desktop\Python\ScopeFoundryProjects\Plant_Macroscope\plant_measure.py", line 111, in measure
    self.dlp_hw.turn_on()
  File "C:\Users\GiorgiaT\OneDrive - Politecnico di Milano\Desktop\Python\ScopeFoundryProjects\DLP_IO_ScopeFoundry\io_hw.py", line 39, in turn_on
    self.dlp.write(self.ON1)
AttributeError: 'IoHW' object has no attribute 'dlp'

