2024-03-20T15:35:27|ERROR|PlantTimeLapseDualMeasure|PlantTimeLapseDualMeasure Failed to update figure1: 'PlantTimeLapseDualMeasure' object has no attribute 'time_index'. ['Traceback (most recent call last):\n', '  File "C:\\Users\\LAB\\anaconda3\\envs\\scopefoundry\\lib\\site-packages\\ScopeFoundry\\measurement.py", line 353, in _on_display_update_timer\n    self.update_display()\n', '  File "C:\\Users\\LAB\\Scopefoundry_projects\\Plant_Macroscope\\plant_timelapse_dual_measure.py", line 93, in update_display\n    self.settings[\'progress\'] = (self.time_index + 1) * 100/length\n', "AttributeError: 'PlantTimeLapseDualMeasure' object has no attribute 'time_index'\n"]
